[Tue Aug 06 13:41:02.352903 2019] [cgi:error] [pid 16972] [client 127.0.0.1:60044] AH01215: Traceback (most recent call last):: /Volumes/DATA/tranngocphu@github.com/conflict-resolution-interface/cdr-interface/python-server/test.py
[Tue Aug 06 13:41:02.353261 2019] [cgi:error] [pid 16972] [client 127.0.0.1:60044] AH01215:   File "/Volumes/DATA/tranngocphu@github.com/conflict-resolution-interface/cdr-interface/python-server/test.py", line 23, in <module>: /Volumes/DATA/tranngocphu@github.com/conflict-resolution-interface/cdr-interface/python-server/test.py
[Tue Aug 06 13:41:02.353309 2019] [cgi:error] [pid 16972] [client 127.0.0.1:60044] AH01215:     fig.savefig("data/img/" + img, bbox_inches='tight'): /Volumes/DATA/tranngocphu@github.com/conflict-resolution-interface/cdr-interface/python-server/test.py
[Tue Aug 06 13:41:02.353383 2019] [cgi:error] [pid 16972] [client 127.0.0.1:60044] AH01215:   File "/Users/Phu/anaconda3/lib/python3.7/site-packages/matplotlib/figure.py", line 2180, in savefig: /Volumes/DATA/tranngocphu@github.com/conflict-resolution-interface/cdr-interface/python-server/test.py
[Tue Aug 06 13:41:02.353433 2019] [cgi:error] [pid 16972] [client 127.0.0.1:60044] AH01215:     self.canvas.print_figure(fname, **kwargs): /Volumes/DATA/tranngocphu@github.com/conflict-resolution-interface/cdr-interface/python-server/test.py
[Tue Aug 06 13:41:02.353526 2019] [cgi:error] [pid 16972] [client 127.0.0.1:60044] AH01215:   File "/Users/Phu/anaconda3/lib/python3.7/site-packages/matplotlib/backend_bases.py", line 2082, in print_figure: /Volumes/DATA/tranngocphu@github.com/conflict-resolution-interface/cdr-interface/python-server/test.py
[Tue Aug 06 13:41:02.353546 2019] [cgi:error] [pid 16972] [client 127.0.0.1:60044] AH01215:     **kwargs): /Volumes/DATA/tranngocphu@github.com/conflict-resolution-interface/cdr-interface/python-server/test.py
[Tue Aug 06 13:41:02.353628 2019] [cgi:error] [pid 16972] [client 127.0.0.1:60044] AH01215:   File "/Users/Phu/anaconda3/lib/python3.7/site-packages/matplotlib/backends/backend_agg.py", line 530, in print_png: /Volumes/DATA/tranngocphu@github.com/conflict-resolution-interface/cdr-interface/python-server/test.py
[Tue Aug 06 13:41:02.353670 2019] [cgi:error] [pid 16972] [client 127.0.0.1:60044] AH01215:     cbook.open_file_cm(filename_or_obj, "wb") as fh:: /Volumes/DATA/tranngocphu@github.com/conflict-resolution-interface/cdr-interface/python-server/test.py
[Tue Aug 06 13:41:02.353730 2019] [cgi:error] [pid 16972] [client 127.0.0.1:60044] AH01215:   File "/Users/Phu/anaconda3/lib/python3.7/contextlib.py", line 112, in __enter__: /Volumes/DATA/tranngocphu@github.com/conflict-resolution-interface/cdr-interface/python-server/test.py
[Tue Aug 06 13:41:02.353755 2019] [cgi:error] [pid 16972] [client 127.0.0.1:60044] AH01215:     return next(self.gen): /Volumes/DATA/tranngocphu@github.com/conflict-resolution-interface/cdr-interface/python-server/test.py
[Tue Aug 06 13:41:02.353839 2019] [cgi:error] [pid 16972] [client 127.0.0.1:60044] AH01215:   File "/Users/Phu/anaconda3/lib/python3.7/site-packages/matplotlib/cbook/__init__.py", line 447, in open_file_cm: /Volumes/DATA/tranngocphu@github.com/conflict-resolution-interface/cdr-interface/python-server/test.py
[Tue Aug 06 13:41:02.353901 2019] [cgi:error] [pid 16972] [client 127.0.0.1:60044] AH01215:     fh, opened = to_filehandle(path_or_file, mode, True, encoding): /Volumes/DATA/tranngocphu@github.com/conflict-resolution-interface/cdr-interface/python-server/test.py
[Tue Aug 06 13:41:02.353996 2019] [cgi:error] [pid 16972] [client 127.0.0.1:60044] AH01215:   File "/Users/Phu/anaconda3/lib/python3.7/site-packages/matplotlib/cbook/__init__.py", line 432, in to_filehandle: /Volumes/DATA/tranngocphu@github.com/conflict-resolution-interface/cdr-interface/python-server/test.py
[Tue Aug 06 13:41:02.354043 2019] [cgi:error] [pid 16972] [client 127.0.0.1:60044] AH01215:     fh = open(fname, flag, encoding=encoding): /Volumes/DATA/tranngocphu@github.com/conflict-resolution-interface/cdr-interface/python-server/test.py
[Tue Aug 06 13:41:02.354109 2019] [cgi:error] [pid 16972] [client 127.0.0.1:60044] AH01215: FileNotFoundError: [Errno 2] No such file or directory: 'data/img/test0.png': /Volumes/DATA/tranngocphu@github.com/conflict-resolution-interface/cdr-interface/python-server/test.py
[Tue Aug 06 13:41:02.393690 2019] [cgi:error] [pid 16972] [client 127.0.0.1:60044] End of script output before headers: test.py
[Tue Aug 06 13:42:40.405286 2019] [cgi:error] [pid 16975] [client 127.0.0.1:60453] AH01215: Traceback (most recent call last):: /Volumes/DATA/tranngocphu@github.com/conflict-resolution-interface/cdr-interface/python-server/test.py
[Tue Aug 06 13:42:40.405632 2019] [cgi:error] [pid 16975] [client 127.0.0.1:60453] AH01215:   File "/Volumes/DATA/tranngocphu@github.com/conflict-resolution-interface/cdr-interface/python-server/test.py", line 25, in <module>: /Volumes/DATA/tranngocphu@github.com/conflict-resolution-interface/cdr-interface/python-server/test.py
[Tue Aug 06 13:42:40.405686 2019] [cgi:error] [pid 16975] [client 127.0.0.1:60453] AH01215:     fig.savefig(path + img, bbox_inches='tight'): /Volumes/DATA/tranngocphu@github.com/conflict-resolution-interface/cdr-interface/python-server/test.py
[Tue Aug 06 13:42:40.405762 2019] [cgi:error] [pid 16975] [client 127.0.0.1:60453] AH01215:   File "/Users/Phu/anaconda3/lib/python3.7/site-packages/matplotlib/figure.py", line 2180, in savefig: /Volumes/DATA/tranngocphu@github.com/conflict-resolution-interface/cdr-interface/python-server/test.py
[Tue Aug 06 13:42:40.405804 2019] [cgi:error] [pid 16975] [client 127.0.0.1:60453] AH01215:     self.canvas.print_figure(fname, **kwargs): /Volumes/DATA/tranngocphu@github.com/conflict-resolution-interface/cdr-interface/python-server/test.py
[Tue Aug 06 13:42:40.405886 2019] [cgi:error] [pid 16975] [client 127.0.0.1:60453] AH01215:   File "/Users/Phu/anaconda3/lib/python3.7/site-packages/matplotlib/backend_bases.py", line 2082, in print_figure: /Volumes/DATA/tranngocphu@github.com/conflict-resolution-interface/cdr-interface/python-server/test.py
[Tue Aug 06 13:42:40.405906 2019] [cgi:error] [pid 16975] [client 127.0.0.1:60453] AH01215:     **kwargs): /Volumes/DATA/tranngocphu@github.com/conflict-resolution-interface/cdr-interface/python-server/test.py
[Tue Aug 06 13:42:40.405989 2019] [cgi:error] [pid 16975] [client 127.0.0.1:60453] AH01215:   File "/Users/Phu/anaconda3/lib/python3.7/site-packages/matplotlib/backends/backend_agg.py", line 530, in print_png: /Volumes/DATA/tranngocphu@github.com/conflict-resolution-interface/cdr-interface/python-server/test.py
[Tue Aug 06 13:42:40.406033 2019] [cgi:error] [pid 16975] [client 127.0.0.1:60453] AH01215:     cbook.open_file_cm(filename_or_obj, "wb") as fh:: /Volumes/DATA/tranngocphu@github.com/conflict-resolution-interface/cdr-interface/python-server/test.py
[Tue Aug 06 13:42:40.406095 2019] [cgi:error] [pid 16975] [client 127.0.0.1:60453] AH01215:   File "/Users/Phu/anaconda3/lib/python3.7/contextlib.py", line 112, in __enter__: /Volumes/DATA/tranngocphu@github.com/conflict-resolution-interface/cdr-interface/python-server/test.py
[Tue Aug 06 13:42:40.406124 2019] [cgi:error] [pid 16975] [client 127.0.0.1:60453] AH01215:     return next(self.gen): /Volumes/DATA/tranngocphu@github.com/conflict-resolution-interface/cdr-interface/python-server/test.py
[Tue Aug 06 13:42:40.406205 2019] [cgi:error] [pid 16975] [client 127.0.0.1:60453] AH01215:   File "/Users/Phu/anaconda3/lib/python3.7/site-packages/matplotlib/cbook/__init__.py", line 447, in open_file_cm: /Volumes/DATA/tranngocphu@github.com/conflict-resolution-interface/cdr-interface/python-server/test.py
[Tue Aug 06 13:42:40.406265 2019] [cgi:error] [pid 16975] [client 127.0.0.1:60453] AH01215:     fh, opened = to_filehandle(path_or_file, mode, True, encoding): /Volumes/DATA/tranngocphu@github.com/conflict-resolution-interface/cdr-interface/python-server/test.py
[Tue Aug 06 13:42:40.406357 2019] [cgi:error] [pid 16975] [client 127.0.0.1:60453] AH01215:   File "/Users/Phu/anaconda3/lib/python3.7/site-packages/matplotlib/cbook/__init__.py", line 432, in to_filehandle: /Volumes/DATA/tranngocphu@github.com/conflict-resolution-interface/cdr-interface/python-server/test.py
[Tue Aug 06 13:42:40.406408 2019] [cgi:error] [pid 16975] [client 127.0.0.1:60453] AH01215:     fh = open(fname, flag, encoding=encoding): /Volumes/DATA/tranngocphu@github.com/conflict-resolution-interface/cdr-interface/python-server/test.py
[Tue Aug 06 13:42:40.406503 2019] [cgi:error] [pid 16975] [client 127.0.0.1:60453] AH01215: PermissionError: [Errno 13] Permission denied: '/Volumes/Data/tranngocphu@github.com/conflict-resolution-interface/cdr-interface/data/img/test0.png': /Volumes/DATA/tranngocphu@github.com/conflict-resolution-interface/cdr-interface/python-server/test.py
[Tue Aug 06 13:42:40.445361 2019] [cgi:error] [pid 16975] [client 127.0.0.1:60453] End of script output before headers: test.py
[Tue Aug 06 15:16:25.752809 2019] [cgi:error] [pid 17349] [client 127.0.0.1:49943] AH02811: script not found or unable to stat: /Volumes/DATA/tranngocphu@github.com/conflict-resolution-interface/cdr-interface/test.py
[Tue Aug 06 16:46:45.583953 2019] [cgi:error] [pid 17352] [client 127.0.0.1:51045] AH01215: (13)Permission denied: exec of '/Volumes/DATA/tranngocphu@github.com/conflict-resolution-interface/cdr-interface/python-server/test1.py' failed: /Volumes/DATA/tranngocphu@github.com/conflict-resolution-interface/cdr-interface/python-server/test1.py
[Tue Aug 06 16:46:45.584169 2019] [cgi:error] [pid 17352] [client 127.0.0.1:51045] End of script output before headers: test1.py
[Tue Aug 06 16:47:24.445991 2019] [cgi:error] [pid 17348] [client 127.0.0.1:51195] AH01215: (13)Permission denied: exec of '/Volumes/DATA/tranngocphu@github.com/conflict-resolution-interface/cdr-interface/python-server/test1.py' failed: /Volumes/DATA/tranngocphu@github.com/conflict-resolution-interface/cdr-interface/python-server/test1.py
[Tue Aug 06 16:47:24.446810 2019] [cgi:error] [pid 17348] [client 127.0.0.1:51195] End of script output before headers: test1.py
[Tue Aug 06 17:02:06.242196 2019] [cgi:error] [pid 17350] [client 127.0.0.1:54860] malformed header from script 'test1.py': Bad header: HTTP/1.0 200 OK, referer: http://interface.local/
[Tue Aug 06 17:04:23.078875 2019] [cgi:error] [pid 16975] [client 127.0.0.1:55440] malformed header from script 'test1.py': Bad header:  PhuPhu TranTran, referer: http://interface.local/
